Workbook

Sheet BBDD
A1: BASE DE DATOS COMERCIAL - GRIFF SALUD
A2: FECHA CONTACTO | B2: MES | C2: NOMBRE | D2: TELEFONO | E2: CANAL | F2: COMERCIAL | G2: LUGAR | H2: ESTADO | I2: PLAN VENDIDO | J2: FECHA ALTA | K2: DÍAS DESDE CONTACTO | L2: CUIL | M2: OS ACTUAL | N2: PLAN ACTUAL | O2: DELEGACIÓN | P2: OBSERVACIONES
A3: 46223 | B3: =IF(A3="","",TEXT(A3,"MM-YYYY")) -> 07-2026 | C3: Micaela | D3: 3517698641 | E3: TERRENO | F3: Sol | G3: CÓRDOBA | H3: En Contacto | K3: =IF(A3="","",TODAY()-A3) -> 17 | P3: esperando rta
A4: 46223 | B4: =IF(A4="","",TEXT(A4,"MM-YYYY")) -> 07-2026 | C4: Victoria | D4: 3518634762 | E4: TERRENO | F4: Sol | G4: CÓRDOBA | H4: Descartado | K4: =IF(A4="","",TODAY()-A4) -> 17 | P4: No Interesa por Costos / APROSS
A5: 46223 | B5: =IF(A5="","",TEXT(A5,"MM-YYYY")) -> 07-2026 | C5: Cristian | D5: 3813695292 | E5: TERRENO | F5: Sol | G5: CÓRDOBA | H5: En Contacto | K5: =IF(A5="","",TODAY()-A5) -> 17 | P5: esperando rta
A6: 46223 | B6: =IF(A6="","",TEXT(A6,"MM-YYYY")) -> 07-2026 | D6: 3512009357 | E6: TERRENO | F6: Sol | G6: CÓRDOBA | H6: En Contacto | K6: =IF(A6="","",TODAY()-A6) -> 17 | P6: esperando rta
A7: 46223 | B7: =IF(A7="","",TEXT(A7,"MM-YYYY")) -> 07-2026 | D7: 3576447836 | E7: TERRENO | F7: Sol | G7: CÓRDOBA | H7: En Contacto | K7: =IF(A7="","",TODAY()-A7) -> 17 | P7: esperando rta
A8: 46223 | B8: =IF(A8="","",TEXT(A8,"MM-YYYY")) -> 07-2026 | D8: 3472584500 | E8: TERRENO | F8: Sol | G8: CÓRDOBA | H8: En Contacto | K8: =IF(A8="","",TODAY()-A8) -> 17 | P8: esperando rta
A9: 46223 | B9: =IF(A9="","",TEXT(A9,"MM-YYYY")) -> 07-2026 | C9: Supervisora | D9: 3512099449 | E9: TERRENO | F9: Sol | G9: CÓRDOBA | H9: Cotizado | K9: =IF(A9="","",TODAY()-A9) -> 17 | P9: Analizando
A10: 46223 | B10: =IF(A10="","",TEXT(A10,"MM-YYYY")) -> 07-2026 | C10: Tamara (referido) | D10: 3515 95-6465 | E10: TERRENO | F10: Sol | G10: CÓRDOBA | H10: Cotizado | K10: =IF(A10="","",TODAY()-A10) -> 17 | P10: Analizando
A11: 46225 | B11: =IF(A11="","",TEXT(A11,"MM-YYYY")) -> 07-2026 | C11: Luis | D11: 3513877479 | E11: TERRENO | F11: Sol | G11: CÓRDOBA | H11: Descartado | K11: =IF(A11="","",TODAY()-A11) -> 15 | P11: Preexistencia / OSPEVIC
A12: 46225 | B12: =IF(A12="","",TEXT(A12,"MM-YYYY")) -> 07-2026 | C12: Luis | D12: 3516157182 | E12: TERRENO | F12: Sol | G12: CÓRDOBA | H12: Cotizado | K12: =IF(A12="","",TODAY()-A12) -> 15 | P12: Analizando
A13: 46225 | B13: =IF(A13="","",TEXT(A13,"MM-YYYY")) -> 07-2026 | C13: Santi | D13: 3512547404 | E13: TERRENO | F13: Sol | G13: CÓRDOBA | H13: En Contacto | K13: =IF(A13="","",TODAY()-A13) -> 15 | P13: esperando rta
A14: 46225 | B14: =IF(A14="","",TEXT(A14,"MM-YYYY")) -> 07-2026 | C14: Hernan | D14: 3512510005 | E14: TERRENO | F14: Sol | G14: CÓRDOBA | H14: En Contacto | K14: =IF(A14="","",TODAY()-A14) -> 15 | P14: esperando rta
A15: 46226 | B15: =IF(A15="","",TEXT(A15,"MM-YYYY")) -> 07-2026 | C15: Fabri | D15: 3512145612 | E15: TERRENO | F15: Sol | G15: CÓRDOBA | H15: En Contacto | K15: =IF(A15="","",TODAY()-A15) -> 14 | P15: esperando rta / SIPSSA
A16: 46226 | B16: =IF(A16="","",TEXT(A16,"MM-YYYY")) -> 07-2026 | C16: Lucio | D16: 3513445175 | E16: TERRENO | F16: Sol | G16: CÓRDOBA | H16: En Contacto | K16: =IF(A16="","",TODAY()-A16) -> 14 | P16: esperando rta / SIPSSA
A17: 46226 | B17: =IF(A17="","",TEXT(A17,"MM-YYYY")) -> 07-2026 | C17: Maycol | D17: 3516345768 | E17: TERRENO | F17: Sol | G17: CÓRDOBA | H17: En Contacto | K17: =IF(A17="","",TODAY()-A17) -> 14 | P17: esperando rta
A18: 46226 | B18: =IF(A18="","",TEXT(A18,"MM-YYYY")) -> 07-2026 | C18: Ivan | D18: 3513837639 | E18: TERRENO | F18: Sol | G18: CÓRDOBA | H18: En Contacto | K18: =IF(A18="","",TODAY()-A18) -> 14 | P18: esperando rta
A19: 46226 | B19: =IF(A19="","",TEXT(A19,"MM-YYYY")) -> 07-2026 | C19: Javier | D19: 3513933807 | E19: TERRENO | F19: Sol | G19: CÓRDOBA | H19: En Contacto | K19: =IF(A19="","",TODAY()-A19) -> 14 | P19: esperando rta
A20: 46226 | B20: =IF(A20="","",TEXT(A20,"MM-YYYY")) -> 07-2026 | C20: Alexis | D20: 3516426155 | E20: TERRENO | F20: Sol | G20: CÓRDOBA | H20: En Contacto | K20: =IF(A20="","",TODAY()-A20) -> 14 | P20: esperando rta
... A45: 46232 | B45: =IF(A45="","",TEXT(A45,"MM-YYYY")) -> 07-2026 | C45: Eric | D45: 3572587668 | E45: TERRENO | F45: Sol | G45: RIO SEGUNDO | H45: En Contacto | K45: =IF(A45="","",TODAY()-A45) -> 8 | P45: esperando rta / OBRA SOCIAL DE LA FÁBRICA - APORTES
A46: 46233 | B46: =IF(A46="","",TEXT(A46,"MM-YYYY")) -> 07-2026 | C46: Brisa | D46: 3547654286 | E46: TERRENO | F46: Sol | H46: Lead | K46: =IF(A46="","",TODAY()-A46) -> 7
A47: 46233 | B47: =IF(A47="","",TEXT(A47,"MM-YYYY")) -> 07-2026 | C47: Bruno | D47: 3547608135 | E47: TERRENO | F47: Sol | H47: Lead | K47: =IF(A47="","",TODAY()-A47) -> 7 | P47: Hector (papá) / APORTE: 17780817
A48: 46233 | B48: =IF(A48="","",TEXT(A48,"MM-YYYY")) -> 07-2026 | C48: Rocio | D48: 3547656197 | E48: TERRENO | F48: Sol | H48: Lead | K48: =IF(A48="","",TODAY()-A48) -> 7
A49: 46234 | B49: =IF(A49="","",TEXT(A49,"MM-YYYY")) -> 07-2026 | C49: Leonardo | D49: 3572609169 | E49: TERRENO | F49: Sol | H49: Lead | K49: =IF(A49="","",TODAY()-A49) -> 6 | P49: Fábrica: LOGROS (Periodo)
A50: 46234 | B50: =IF(A50="","",TEXT(A50,"MM-YYYY")) -> 07-2026 | C50: Angel | D50: 3572606463 | E50: TERRENO | F50: Sol | H50: Lead | K50: =IF(A50="","",TODAY()-A50) -> 6 | P50: OBRA SOCIAL - Fábrica
A51: 46234 | B51: =IF(A51="","",TEXT(A51,"MM-YYYY")) -> 07-2026 | C51: Daniel | D51: 3572447843 | E51: TERRENO | F51: Sol | H51: Lead | K51: =IF(A51="","",TODAY()-A51) -> 6
A52: 46223 | B52: =IF(A52="","",TEXT(A52,"MM-YYYY")) -> 07-2026 | C52: 3515585305 | D52: Javier chaparro | E52: TERRENO | F52: Juli | H52: Descartado | K52: =IF(A52="","",TODAY()-A52) -> 17 | P52: No puede Desregular / Base Miercoles
A53: 46223 | B53: =IF(A53="","",TEXT(A53,"MM-YYYY")) -> 07-2026 | C53: 3515133675 | D53: Matias Mariño | E53: TERRENO | F53: Juli | H53: Descartado | K53: =IF(A53="","",TODAY()-A53) -> 17 | P53: No puede Desregular / Zona miercoles
A54: 46223 | B54: =IF(A54="","",TEXT(A54,"MM-YYYY")) -> 07-2026 | C54: 3513223740 | D54: Miguel Sanchez | E54: TERRENO | F54: Juli | H54: Descartado | K54: =IF(A54="","",TODAY()-A54) -> 17 | P54: quiere permanecer en gea por costos y por el Sanotorio Allende / Zona miercoles
A55: 46223 | B55: =IF(A55="","",TEXT(A55,"MM-YYYY")) -> 07-2026 | C55: 3576477300 | D55: Tomas Rio | E55: TERRENO | F55: Juli | H55: En Contacto | K55: =IF(A55="","",TODAY()-A55) -> 17 | P55: llame y mande msjs y no respondio nunca / Zona miercoles
A56: 46225 | B56: =IF(A56="","",TEXT(A56,"MM-YYYY")) -> 07-2026 | C56: 3512465207 | D56: Paolo Albertini | E56: TERRENO | F56: Juli | H56: Cotizado | K56: =IF(A56="","",TODAY()-A56) -> 15 | P56: Analizando / Zona miercoles
A57: 46226 | B57: =IF(A57="","",TEXT(A57,"MM-YYYY")) -> 07-2026 | C57: 3518107536 | D57: Monica Carrizo | E57: TERRENO | F57: Juli | H57: En Contacto | K57: =IF(A57="","",TODAY()-A57) -> 14 | P57: No responde llamada ni Mensajes / Porta jueves
A58: 46226 | B58: =IF(A58="","",TEXT(A58,"MM-YYYY")) -> 07-2026 | C58: 3512839355 | D58: Ricardo Santa Cuz | E58: TERRENO | F58: Juli | H58: Cotizado | K58: =IF(A58="","",TODAY()-A58) -> 14 | P58: Analizando / Urea Automotor
A59: 46226 | B59: =IF(A59="","",TEXT(A59,"MM-YYYY")) -> 07-2026 | C59: 3517558689 | D59: Rodrigo Abdala | E59: TERRENO | F59: Juli | H59: Descartado | K59: =IF(A59="","",TODAY()-A59) -> 14 | P59: No puede Desregular / Urea Automotor
A60: 46226 | B60: =IF(A60="","",TEXT(A60,"MM-YYYY")) -> 07-2026 | C60: 3513839599 | D60: Maximiliano Varela | E60: TERRENO | F60: Juli | H60: Descartado | K60: =IF(A60="","",TODAY()-A60) -> 14 | P60: Premedic/ No puede Desregular / ITV
A61: 46226 | B61: =IF(A61="","",TEXT(A61,"MM-YYYY")) -> 07-2026 | C61: 3515949702 | D61: Arce Nicolas | E61: TERRENO | F61: Juli | H61: En Contacto | K61: =IF(A61="","",TODAY()-A61) -> 14 | P61: llame varias veces y no respondio ni llamadasni msj / ITV
A62: 46226 | B62: =IF(A62="","",TEXT(A62,"MM-YYYY")) -> 07-2026 | C62: 3515435436 | D62: Esteban Avila | E62: TERRENO | F62: Juli | H62: Descartado | K62: =IF(A62="","",TODAY()-A62) -> 14 | P62: quiere permanecer en gea por costos y por el Sanotorio Allende / Cauplas
A63: 46226 | B63: =IF(A63="","",TEXT(A63,"MM-YYYY")) -> 07-2026 | C63: 3513998072 | D63: Pablo Castillo | E63: TERRENO | F63: Juli | H63: Descartado | K63: =IF(A63="","",TODAY()-A63) -> 14 | P63: quiere permanecer en su O.S por costos / Vidrios
... A66: 46227 | B66: =IF(A66="","",TEXT(A66,"MM-YYYY")) -> 07-2026 | C66: 3518128055 | D66: Alejandro Zarraja | E66: TERRENO | F66: Juli | H66: En Contacto | K66: =IF(A66="","",TODAY()-A66) -> 13 | P66: No responde llamada ni Mensajes / plaza
...

Sheet RESUMEN
A1: RESUMEN COMERCIAL
A3: POR ESTADO | D3: POR COMERCIAL
A4: Lead | B4: =COUNTIF(BBDD!H:H,"Lead") -> 8 | D4: Sol | E4: =COUNTIF(BBDD!F:F,"Sol") -> 49
A5: En Contacto | B5: =COUNTIF(BBDD!H:H,"En Contacto") -> 220 | D5: Vane | E5: =COUNTIF(BBDD!F:F,"Vane") -> 133
A6: Cotizado | B6: =COUNTIF(BBDD!H:H,"Cotizado") -> 30 | D6: Juli | E6: =COUNTIF(BBDD!F:F,"Juli") -> 128
A7: Cerrado | B7: =COUNTIF(BBDD!H:H,"Cerrado") -> 3
A8: Descartado | B8: =COUNTIF(BBDD!H:H,"Descartado") -> 49
A10: VENTAS GS200 | B10: =COUNTIF(BBDD!I:I,"GS200") -> 3
A11: VENTAS GS100 | B11: =COUNTIF(BBDD!I:I,"GS100") -> 0
A12: TOTAL LEADS | B12: =COUNTA(BBDD!C:C)-1 -> 306

Sheet LISTAS
A1: ESTADO | B1: CANAL | C1: COMERCIAL | D1: PLAN_VENDIDO
A2: Lead | B2: TERRENO | C2: Sol | D2: GS100
A3: En Contacto | B3: OSPIF | C3: Vane | D3: GS200
A4: Cotizado | C4: Juli
A5: Cerrado
A6: Descartado
